Workbook

Sheet ABS
A1: Original Data | J1: Specific Values
A2: Index Value | B2: Infill Type | C2: Infill Concentration | D2: Border number | E2: Mass (g) | F2: Ultimate Tensile Strength (kN) | G2: Modulus of Elasticity (MPa) | H2: Modulus of Resilience (MPa) | I2: Yield Strength (kN) | J2: Specific UTS ( kN/g) | K2: Specific Modulus of Elasticity (MPa/g) | L2: Specific Modulus of Resilience (MPa/g) | M2: Specifc Yield Strength (kN/g)
A3: 1 | B3: N/a | C3: 1 | D3: Inf | E3: 61.3 | F3: 6.6299 | G3: 823.48 | H3: 0.235 | I3: 3.4478 | J3: =Table2[[#This Row],[Ultimate Tensile Strength (kN)]]/Table2[[#This Row],[Mass (g)]] -> 0.10815498 | K3: =Table2[[#This Row],[Modulus of Elasticity (MPa)]]/Table2[[#This Row],[Mass (g)]] -> 13.433605 | L3: =Table2[[#This Row],[Modulus of Resilience (MPa)]]/Table2[[#This Row],[Mass (g)]] -> 0.0038336052 | M3: =Table2[[#This Row],[Yield Strength (kN)]]/Table2[[#This Row],[Mass (g)]] -> 0.056244698
A4: 2 | B4: N/a | C4: 0 | D4: 2 | E4: 20 | F4: 1.6811 | G4: 268.27 | H4: 0.0293 | I4: 0.6821 | J4: =Table2[[#This Row],[Ultimate Tensile Strength (kN)]]/Table2[[#This Row],[Mass (g)]] -> 0.084055 | K4: =Table2[[#This Row],[Modulus of Elasticity (MPa)]]/Table2[[#This Row],[Mass (g)]] -> 13.4135 | L4: =Table2[[#This Row],[Modulus of Resilience (MPa)]]/Table2[[#This Row],[Mass (g)]] -> 0.001465 | M4: =Table2[[#This Row],[Yield Strength (kN)]]/Table2[[#This Row],[Mass (g)]] -> 0.034105
A5: 3 | B5: N/a | C5: 0 | D5: 3 | E5: 25.5 | F5: 2.8112 | G5: 388.75 | H5: 0.0323 | I5: 0.8567 | J5: =Table2[[#This Row],[Ultimate Tensile Strength (kN)]]/Table2[[#This Row],[Mass (g)]] -> 0.11024314 | K5: =Table2[[#This Row],[Modulus of Elasticity (MPa)]]/Table2[[#This Row],[Mass (g)]] -> 15.245098 | L5: =Table2[[#This Row],[Modulus of Resilience (MPa)]]/Table2[[#This Row],[Mass (g)]] -> 0.0012666667 | M5: =Table2[[#This Row],[Yield Strength (kN)]]/Table2[[#This Row],[Mass (g)]] -> 0.033596078
A6: 4 | B6: Grid | C6: 0.1 | D6: 2 | E6: 19.2 | F6: 1.335 | G6: 205.66 | H6: 0.0207 | I6: 0.5052 | J6: =Table2[[#This Row],[Ultimate Tensile Strength (kN)]]/Table2[[#This Row],[Mass (g)]] -> 0.06953125 | K6: =Table2[[#This Row],[Modulus of Elasticity (MPa)]]/Table2[[#This Row],[Mass (g)]] -> 10.711458 | L6: =Table2[[#This Row],[Modulus of Resilience (MPa)]]/Table2[[#This Row],[Mass (g)]] -> 0.001078125 | M6: =Table2[[#This Row],[Yield Strength (kN)]]/Table2[[#This Row],[Mass (g)]] -> 0.0263125
A7: 5 | B7: Grid | C7: 0.25 | D7: 2 | E7: 26 | F7: 1.445 | G7: 201.67 | H7: 0.061 | I7: 0.8843 | J7: =Table2[[#This Row],[Ultimate Tensile Strength (kN)]]/Table2[[#This Row],[Mass (g)]] -> 0.055576923 | K7: =Table2[[#This Row],[Modulus of Elasticity (MPa)]]/Table2[[#This Row],[Mass (g)]] -> 7.7565385 | L7: =Table2[[#This Row],[Modulus of Resilience (MPa)]]/Table2[[#This Row],[Mass (g)]] -> 0.0023461538 | M7: =Table2[[#This Row],[Yield Strength (kN)]]/Table2[[#This Row],[Mass (g)]] -> 0.034011538
A8: 6 | B8: Cubic | C8: 0.1 | D8: 2 | E8: 19 | F8: 1.4693 | G8: 227.06 | H8: 0.0161 | I8: 0.4627 | J8: =Table2[[#This Row],[Ultimate Tensile Strength (kN)]]/Table2[[#This Row],[Mass (g)]] -> 0.077331579 | K8: =Table2[[#This Row],[Modulus of Elasticity (MPa)]]/Table2[[#This Row],[Mass (g)]] -> 11.950526 | L8: =Table2[[#This Row],[Modulus of Resilience (MPa)]]/Table2[[#This Row],[Mass (g)]] -> 0.00084736842 | M8: =Table2[[#This Row],[Yield Strength (kN)]]/Table2[[#This Row],[Mass (g)]] -> 0.024352632
A9: 7 | B9: Cubic | C9: 0.25 | D9: 2 | E9: 26.1 | F9: 1.8183 | G9: 250.75 | H9: 0.0893 | I9: 1.1915 | J9: =Table2[[#This Row],[Ultimate Tensile Strength (kN)]]/Table2[[#This Row],[Mass (g)]] -> 0.069666667 | K9: =Table2[[#This Row],[Modulus of Elasticity (MPa)]]/Table2[[#This Row],[Mass (g)]] -> 9.6072797 | L9: =Table2[[#This Row],[Modulus of Resilience (MPa)]]/Table2[[#This Row],[Mass (g)]] -> 0.0034214559 | M9: =Table2[[#This Row],[Yield Strength (kN)]]/Table2[[#This Row],[Mass (g)]] -> 0.045651341
A10: 8 | B10: Gyroid | C10: 0.1 | D10: 2 | E10: 19 | F10: 1.4343 | G10: 190.34 | H10: 0.0587 | I10: 0.8357 | J10: =Table2[[#This Row],[Ultimate Tensile Strength (kN)]]/Table2[[#This Row],[Mass (g)]] -> 0.075489474 | K10: =Table2[[#This Row],[Modulus of Elasticity (MPa)]]/Table2[[#This Row],[Mass (g)]] -> 10.017895 | L10: =Table2[[#This Row],[Modulus of Resilience (MPa)]]/Table2[[#This Row],[Mass (g)]] -> 0.0030894737 | M10: =Table2[[#This Row],[Yield Strength (kN)]]/Table2[[#This Row],[Mass (g)]] -> 0.043984211
A11: 9 | B11: Gyroid | C11: 0.25 | D11: 2 | E11: 25.6 | F11: 1.5629 | G11: 238.64 | H11: 0.0256 | I11: 0.6075 | J11: =Table2[[#This Row],[Ultimate Tensile Strength (kN)]]/Table2[[#This Row],[Mass (g)]] -> 0.061050781 | K11: =Table2[[#This Row],[Modulus of Elasticity (MPa)]]/Table2[[#This Row],[Mass (g)]] -> 9.321875 | L11: =Table2[[#This Row],[Modulus of Resilience (MPa)]]/Table2[[#This Row],[Mass (g)]] -> 0.001 | M11: =Table2[[#This Row],[Yield Strength (kN)]]/Table2[[#This Row],[Mass (g)]] -> 0.023730469
A12: 10 | B12: Grid | C12: 0.1 | D12: 3 | E12: 24.5 | F12: 1.8508 | G12: 252.92 | H12: 0.0791 | I12: 1.1189 | J12: =Table2[[#This Row],[Ultimate Tensile Strength (kN)]]/Table2[[#This Row],[Mass (g)]] -> 0.075542857 | K12: =Table2[[#This Row],[Modulus of Elasticity (MPa)]]/Table2[[#This Row],[Mass (g)]] -> 10.323265 | L12: =Table2[[#This Row],[Modulus of Resilience (MPa)]]/Table2[[#This Row],[Mass (g)]] -> 0.0032285714 | M12: =Table2[[#This Row],[Yield Strength (kN)]]/Table2[[#This Row],[Mass (g)]] -> 0.045669388
A13: 11 | B13: Grid | C13: 0.25 | D13: 3 | E13: 30.8 | F13: 2.1374 | G13: 276.22 | H13: 0.1307 | I13: 1.518 | J13: =Table2[[#This Row],[Ultimate Tensile Strength (kN)]]/Table2[[#This Row],[Mass (g)]] -> 0.069396104 | K13: =Table2[[#This Row],[Modulus of Elasticity (MPa)]]/Table2[[#This Row],[Mass (g)]] -> 8.9681818 | L13: =Table2[[#This Row],[Modulus of Resilience (MPa)]]/Table2[[#This Row],[Mass (g)]] -> 0.0042435065 | M13: =Table2[[#This Row],[Yield Strength (kN)]]/Table2[[#This Row],[Mass (g)]] -> 0.049285714
A14: 12 | B14: Cubic | C14: 0.1 | D14: 3 | E14: 24.6 | F14: 2.0702 | G14: 318.51 | H14: 0.0202 | I14: 0.6075 | J14: =Table2[[#This Row],[Ultimate Tensile Strength (kN)]]/Table2[[#This Row],[Mass (g)]] -> 0.084154472 | K14: =Table2[[#This Row],[Modulus of Elasticity (MPa)]]/Table2[[#This Row],[Mass (g)]] -> 12.947561 | L14: =Table2[[#This Row],[Modulus of Resilience (MPa)]]/Table2[[#This Row],[Mass (g)]] -> 0.00082113821 | M14: =Table2[[#This Row],[Yield Strength (kN)]]/Table2[[#This Row],[Mass (g)]] -> 0.024695122
A15: 13 | B15: Cubic | C15: 0.25 | D15: 3 | E15: 30.8 | F15: 2.3705 | G15: 326.7 | H15: 0.1067 | I15: 1.4839 | J15: =Table2[[#This Row],[Ultimate Tensile Strength (kN)]]/Table2[[#This Row],[Mass (g)]] -> 0.076964286 | K15: =Table2[[#This Row],[Modulus of Elasticity (MPa)]]/Table2[[#This Row],[Mass (g)]] -> 10.607143 | L15: =Table2[[#This Row],[Modulus of Resilience (MPa)]]/Table2[[#This Row],[Mass (g)]] -> 0.0034642857 | M15: =Table2[[#This Row],[Yield Strength (kN)]]/Table2[[#This Row],[Mass (g)]] -> 0.048178571
... A17: 15 | B17: Gyroid | C17: 0.25 | D17: 3 | E17: 30.4 | F17: 2.1361 | G17: 285.92 | H17: 0.0969 | I17: 1.3223 | J17: =Table2[[#This Row],[Ultimate Tensile Strength (kN)]]/Table2[[#This Row],[Mass (g)]] -> 0.070266447 | K17: =Table2[[#This Row],[Modulus of Elasticity (MPa)]]/Table2[[#This Row],[Mass (g)]] -> 9.4052632 | L17: =Table2[[#This Row],[Modulus of Resilience (MPa)]]/Table2[[#This Row],[Mass (g)]] -> 0.0031875 | M17: =Table2[[#This Row],[Yield Strength (kN)]]/Table2[[#This Row],[Mass (g)]] -> 0.043496711
A18: Comparison - Infills
B19: Infill Type | C19: Average Values for Given Infill | E19: Mass (g) | F19: Ultimate Tensile Strength (kN) | G19: Modulus of Elasticity (MPA) | H19: Modulus of Resilience | I19: Yield Strength (kN) | J19: Specific UTS ( kN/g) | K19: Specific Modulus of Elasticity (MPa/g) | L19: Specific Modulus of Resilience (MPa/g) | M19: Specifc Yield Strength (kN/g)
B20: Grid | E20: =(SUM(E6:E7)+SUM(E12:E13))/4 -> 25.125 | F20: =(SUM(F6:F7)+SUM(F12:F13))/4 -> 1.69205 | G20: =(SUM(G6:G7)+SUM(G12:G13))/4 -> 234.1175 | H20: =(SUM(H6:H7)+SUM(H12:H13))/4 -> 0.072875 | I20: =(SUM(I6:I7)+SUM(I12:I13))/4 -> 1.0066 | J20: =(SUM(J6:J7)+SUM(J12:J13))/4 -> 0.067511784 | K20: =(SUM(K6:K7)+SUM(K12:K13))/4 -> 9.439861 | L20: =(SUM(L6:L7)+SUM(L12:L13))/4 -> 0.0027240892 | M20: =(SUM(M6:M7)+SUM(M12:M13))/4 -> 0.038819785
B21: Cubic | E21: =(E8+E9+E14+E15)/4 -> 25.125 | F21: =(F8+F9+F14+F15)/4 -> 1.932075 | G21: =(G8+G9+G14+G15)/4 -> 280.755 | H21: =(H8+H9+H14+H15)/4 -> 0.058075 | I21: =(I8+I9+I14+I15)/4 -> 0.9364 | J21: =(J8+J9+J14+J15)/4 -> 0.077029251 | K21: =(K8+K9+K14+K15)/4 -> 11.278127 | L21: =(L8+L9+L14+L15)/4 -> 0.0021385621 | M21: =(M8+M9+M14+M15)/4 -> 0.035719416
B22: Gyroid | E22: =(E10+E11+E16+E17)/4 -> 24.9 | F22: =(F10+F11+F16+F17)/4 -> 1.750525 | G22: =(G10+G11+G16+G17)/4 -> 248.08 | H22: =(H10+H11+H16+H17)/4 -> 0.0551 | I22: =(I10+I11+I16+I17)/4 -> 0.894825 | J22: =(J10+J11+J16+J17)/4 -> 0.070693545 | K22: =(K10+K11+K16+K17)/4 -> 10.005567 | L22: =(L10+L11+L16+L17)/4 -> 0.0022176174 | M22: =(M10+M11+M16+M17)/4 -> 0.036073173
A23: Comparison - Infill Density
C24: Infill Concentration | D24: Average Values for Given Infill Density | E24: Mass (g) | F24: Ultimate Tensile Strength (kN) | G24: Modulus of Elasticity (MPA) | H24: Modulus of Resilience | I24: Yield Strength (kN) | J24: Ultimate Tensile Strength (kN) | K24: Modulus of Elasticity (MPA) | L24: Modulus of Resilience | M24: Yield Strength (kN/g)
C25: 0 | E25: =(SUM(E4:E5))/2 -> 22.75 | F25: =(SUM(F4:F5))/2 -> 2.24615 | G25: =(SUM(G4:G5))/2 -> 328.51 | H25: =(SUM(H4:H5))/2 -> 0.0308 | I25: =(SUM(I4:I5))/2 -> 0.7694 | J25: =(SUM(J4:J5))/2 -> 0.097149069 | K25: =(SUM(K4:K5))/2 -> 14.329299 | L25: =(SUM(L4:L5))/2 -> 0.0013658333 | M25: =(SUM(M4:M5))/2 -> 0.033850539
C26: 0.1 | E26: =(E6+E8+E10+E12+E14+E16)/6 -> 21.816667 | F26: =(F6+F8+F10+F12+F14+F16)/6 -> 1.6714 | G26: =(G6+G8+G10+G12+G14+G16)/6 -> 245.31833 | H26: =(H6+H8+H10+H12+H14+H16)/6 -> 0.039 | I26: =(I6+I8+I10+I12+I14+I16)/6 -> 0.72396667 | J26: =(J6+J8+J10+J12+J14+J16)/6 -> 0.076336185 | K26: =(K6+K8+K10+K12+K14+K16)/6 -> 11.204657 | L26: =(L6+L8+L10+L12+L14+L16)/6 -> 0.0017763621 | M26: =(M6+M8+M10+M12+M14+M16)/6 -> 0.033015859
C27: 0.25 | E27: =(E7+E9+E11+E13+E15+E17)/6 -> 28.283333 | F27: =(F7+F9+F11+F13+F15+F17)/6 -> 1.9117 | G27: =(G7+G9+G11+G13+G15+G17)/6 -> 263.31667 | H27: =(H7+H9+H11+H13+H15+H17)/6 -> 0.085033333 | I27: =(I7+I9+I11+I13+I15+I17)/6 -> 1.1679167 | J27: =(J7+J9+J11+J13+J15+J17)/6 -> 0.067153535 | K27: =(K7+K9+K11+K13+K15+K17)/6 -> 9.2777135 | L27: =(L7+L9+L11+L13+L15+L17)/6 -> 0.002943817 | M27: =(M7+M9+M11+M13+M15+M17)/6 -> 0.040725724
C28: 1 | E28: =E3 -> 61.3 | F28: =F3 -> 6.6299 | G28: =G3 -> 823.48 | H28: =H3 -> 0.235 | I28: =I3 -> 3.4478 | J28: =J3 -> 0.10815498 | K28: =K3 -> 13.433605 | L28: =L3 -> 0.0038336052 | M28: =M3 -> 0.056244698
A29: Comparison - Border #
A30: Average Values for Given Border # | D30: Border number | E30: Mass (g) | F30: Ultimate Tensile Strength (kN) | G30: Modulus of Elasticity (MPA) | H30: Modulus of Resilience | I30: Yield Strength (kN) | J30: Ultimate Tensile Strength (kN) | K30: Modulus of Elasticity (MPA) | L30: Modulus of Resilience | M30: Yield Strength (kN/g)
D31: 2 | E31: =(E4+SUM(E6:E11))/7 -> 22.128571 | F31: =(F4+SUM(F6:F11))/7 -> 1.5351286 | G31: =(G4+SUM(G6:G11))/7 -> 226.05571 | H31: =(H4+SUM(H6:H11))/7 -> 0.042957143 | I31: =(I4+SUM(I6:I11))/7 -> 0.73842857 | J31: =(J4+SUM(J6:J11))/7 -> 0.070385953 | K31: =(K4+SUM(K6:K11))/7 -> 10.39701 | L31: =(L4+SUM(L6:L11))/7 -> 0.001892511 | M31: =(M4+SUM(M6:M11))/7 -> 0.033163956
D32: 3 | E32: =(E5+SUM(E12:E17))/7 -> 27.314286 | F32: =(F5+SUM(F12:F17))/7 -> 2.1778571 | G32: =(G5+SUM(G12:G17))/7 -> 303.77714 | H32: =(H5+SUM(H12:H17))/7 -> 0.072157143 | I32: =(I5+SUM(I12:I17))/7 -> 1.1030143 | J32: =(J5+SUM(J12:J17))/7 -> 0.080362112 | K32: =(K5+SUM(K12:K17))/7 -> 11.253393 | L32: =(L5+SUM(L12:L17))/7 -> 0.0025435949 | M32: =(M5+SUM(M12:M17))/7 -> 0.039714698

Sheet PLA
A1: Original Data | J1: Specific (divided by mass)
A2: Index Value | B2: Infill Type | C2: Infill Concentration | D2: Border number | E2: Mass (g) | F2: Ultimate Tensile Strength (kN) | G2: Modulus of Elasticity (MPa) | H2: Modulus of Resilience (MPa) | I2: Yield Strength (kN) | J2: Specific UTS (kN/g) | K2: Specific Modulus of Elasticity (MPa/g) | L2: Specific Modulus of Resilience (MPa/g) | M2: Specifc Yield Strength (kN)
A3: 1 | B3: N/a | C3: 1 | D3: Inf | E3: 73 | F3: 9.3463 | G3: 1280.88 | H3: 0.1056 | I3: 2.6982 | J3: =Table24[[#This Row],[Ultimate Tensile Strength (kN)]]/Table24[[#This Row],[Mass (g)]] -> 0.12803151 | K3: =Table24[[#This Row],[Modulus of Elasticity (MPa)]]/Table24[[#This Row],[Mass (g)]] -> 17.546301 | L3: =Table24[[#This Row],[Modulus of Resilience (MPa)]]/Table24[[#This Row],[Mass (g)]] -> 0.0014465753 | M3: =Table24[[#This Row],[Yield Strength (kN)]]/Table24[[#This Row],[Mass (g)]] -> 0.036961644
A4: 2 | B4: N/a | C4: 0 | D4: 2 | E4: 16.7 | F4: 1.6182 | G4: 211.47 | H4: 0.0327 | I4: 0.6491 | J4: =Table24[[#This Row],[Ultimate Tensile Strength (kN)]]/Table24[[#This Row],[Mass (g)]] -> 0.096898204 | K4: =Table24[[#This Row],[Modulus of Elasticity (MPa)]]/Table24[[#This Row],[Mass (g)]] -> 12.662874 | L4: =Table24[[#This Row],[Modulus of Resilience (MPa)]]/Table24[[#This Row],[Mass (g)]] -> 0.0019580838 | M4: =Table24[[#This Row],[Yield Strength (kN)]]/Table24[[#This Row],[Mass (g)]] -> 0.038868263
A5: 3 | B5: N/a | C5: 0 | D5: 3 | E5: 24.1 | F5: 2.4347 | G5: 354.94 | H5: 0.0235 | I5: 0.693 | J5: =Table24[[#This Row],[Ultimate Tensile Strength (kN)]]/Table24[[#This Row],[Mass (g)]] -> 0.1010249 | K5: =Table24[[#This Row],[Modulus of Elasticity (MPa)]]/Table24[[#This Row],[Mass (g)]] -> 14.727801 | L5: =Table24[[#This Row],[Modulus of Resilience (MPa)]]/Table24[[#This Row],[Mass (g)]] -> 0.00097510373 | M5: =Table24[[#This Row],[Yield Strength (kN)]]/Table24[[#This Row],[Mass (g)]] -> 0.028755187
A6: 4 | B6: Grid | C6: 0.1 | D6: 2 | E6: 23 | F6: 1.7476 | G6: 254.67 | H6: 0.0798 | I6: 1.1251 | J6: =Table24[[#This Row],[Ultimate Tensile Strength (kN)]]/Table24[[#This Row],[Mass (g)]] -> 0.075982609 | K6: =Table24[[#This Row],[Modulus of Elasticity (MPa)]]/Table24[[#This Row],[Mass (g)]] -> 11.072609 | L6: =Table24[[#This Row],[Modulus of Resilience (MPa)]]/Table24[[#This Row],[Mass (g)]] -> 0.0034695652 | M6: =Table24[[#This Row],[Yield Strength (kN)]]/Table24[[#This Row],[Mass (g)]] -> 0.048917391
A7: 5 | B7: Grid | C7: 0.25 | D7: 2 | E7: 35.1 | F7: 2.4642 | G7: 369.98 | H7: 0.135 | I7: 1.7471 | J7: =Table24[[#This Row],[Ultimate Tensile Strength (kN)]]/Table24[[#This Row],[Mass (g)]] -> 0.070205128 | K7: =Table24[[#This Row],[Modulus of Elasticity (MPa)]]/Table24[[#This Row],[Mass (g)]] -> 10.540741 | L7: =Table24[[#This Row],[Modulus of Resilience (MPa)]]/Table24[[#This Row],[Mass (g)]] -> 0.0038461538 | M7: =Table24[[#This Row],[Yield Strength (kN)]]/Table24[[#This Row],[Mass (g)]] -> 0.049774929
A8: 6 | B8: Cubic | C8: 0.1 | D8: 2 | E8: 22.9 | F8: 2.1302 | G8: 319.06 | H8: 0.0673 | I8: 1.1478 | J8: =Table24[[#This Row],[Ultimate Tensile Strength (kN)]]/Table24[[#This Row],[Mass (g)]] -> 0.093021834 | K8: =Table24[[#This Row],[Modulus of Elasticity (MPa)]]/Table24[[#This Row],[Mass (g)]] -> 13.932751 | L8: =Table24[[#This Row],[Modulus of Resilience (MPa)]]/Table24[[#This Row],[Mass (g)]] -> 0.0029388646 | M8: =Table24[[#This Row],[Yield Strength (kN)]]/Table24[[#This Row],[Mass (g)]] -> 0.050122271
A9: 7 | B9: Cubic | C9: 0.25 | D9: 2 | E9: 31.3 | F9: 2.6031 | G9: 390.65 | H9: 0.1223 | I9: 1.731 | J9: =Table24[[#This Row],[Ultimate Tensile Strength (kN)]]/Table24[[#This Row],[Mass (g)]] -> 0.083166134 | K9: =Table24[[#This Row],[Modulus of Elasticity (MPa)]]/Table24[[#This Row],[Mass (g)]] -> 12.480831 | L9: =Table24[[#This Row],[Modulus of Resilience (MPa)]]/Table24[[#This Row],[Mass (g)]] -> 0.0039073482 | M9: =Table24[[#This Row],[Yield Strength (kN)]]/Table24[[#This Row],[Mass (g)]] -> 0.055303514
A10: 8 | B10: Gyroid | C10: 0.1 | D10: 2 | E10: 23 | F10: 2.0438 | G10: 295.55 | H10: 0.0814 | I10: 1.2307 | J10: =Table24[[#This Row],[Ultimate Tensile Strength (kN)]]/Table24[[#This Row],[Mass (g)]] -> 0.08886087 | K10: =Table24[[#This Row],[Modulus of Elasticity (MPa)]]/Table24[[#This Row],[Mass (g)]] -> 12.85 | L10: =Table24[[#This Row],[Modulus of Resilience (MPa)]]/Table24[[#This Row],[Mass (g)]] -> 0.0035391304 | M10: =Table24[[#This Row],[Yield Strength (kN)]]/Table24[[#This Row],[Mass (g)]] -> 0.053508696
A11: 9 | B11: Gyroid | C11: 0.25 | D11: 2 | E11: 31 | F11: 2.3404 | G11: 332.1 | H11: 0.1101 | I11: 1.5126 | J11: =Table24[[#This Row],[Ultimate Tensile Strength (kN)]]/Table24[[#This Row],[Mass (g)]] -> 0.075496774 | K11: =Table24[[#This Row],[Modulus of Elasticity (MPa)]]/Table24[[#This Row],[Mass (g)]] -> 10.712903 | L11: =Table24[[#This Row],[Modulus of Resilience (MPa)]]/Table24[[#This Row],[Mass (g)]] -> 0.0035516129 | M11: =Table24[[#This Row],[Yield Strength (kN)]]/Table24[[#This Row],[Mass (g)]] -> 0.048793548
A12: 10 | B12: Grid | C12: 0.1 | D12: 3 | E12: 29.6 | F12: 2.8334 | G12: 403.11 | H12: 0.1157 | I12: 1.7044 | J12: =Table24[[#This Row],[Ultimate Tensile Strength (kN)]]/Table24[[#This Row],[Mass (g)]] -> 0.095722973 | K12: =Table24[[#This Row],[Modulus of Elasticity (MPa)]]/Table24[[#This Row],[Mass (g)]] -> 13.618581 | L12: =Table24[[#This Row],[Modulus of Resilience (MPa)]]/Table24[[#This Row],[Mass (g)]] -> 0.0039087838 | M12: =Table24[[#This Row],[Yield Strength (kN)]]/Table24[[#This Row],[Mass (g)]] -> 0.057581081
A13: 11 | B13: Grid | C13: 0.25 | D13: 3 | E13: 36.9 | F13: 2.8868 | G13: 414.66 | H13: 0.1236 | I13: 1.7942 | J13: =Table24[[#This Row],[Ultimate Tensile Strength (kN)]]/Table24[[#This Row],[Mass (g)]] -> 0.078233062 | K13: =Table24[[#This Row],[Modulus of Elasticity (MPa)]]/Table24[[#This Row],[Mass (g)]] -> 11.237398 | L13: =Table24[[#This Row],[Modulus of Resilience (MPa)]]/Table24[[#This Row],[Mass (g)]] -> 0.0033495935 | M13: =Table24[[#This Row],[Yield Strength (kN)]]/Table24[[#This Row],[Mass (g)]] -> 0.048623306
A14: 12 | B14: Cubic | C14: 0.1 | D14: 3 | E14: 29.5 | F14: 2.8893 | G14: 423.57 | H14: 0.0704 | I14: 1.35 | J14: =Table24[[#This Row],[Ultimate Tensile Strength (kN)]]/Table24[[#This Row],[Mass (g)]] -> 0.097942373 | K14: =Table24[[#This Row],[Modulus of Elasticity (MPa)]]/Table24[[#This Row],[Mass (g)]] -> 14.358305 | L14: =Table24[[#This Row],[Modulus of Resilience (MPa)]]/Table24[[#This Row],[Mass (g)]] -> 0.0023864407 | M14: =Table24[[#This Row],[Yield Strength (kN)]]/Table24[[#This Row],[Mass (g)]] -> 0.045762712
A15: 13 | B15: Cubic | C15: 0.25 | D15: 3 | E15: 36.9 | F15: 3.2658 | G15: 483.77 | H15: 0.1337 | I15: 2.0056 | J15: =Table24[[#This Row],[Ultimate Tensile Strength (kN)]]/Table24[[#This Row],[Mass (g)]] -> 0.088504065 | K15: =Table24[[#This Row],[Modulus of Elasticity (MPa)]]/Table24[[#This Row],[Mass (g)]] -> 13.110298 | L15: =Table24[[#This Row],[Modulus of Resilience (MPa)]]/Table24[[#This Row],[Mass (g)]] -> 0.0036233062 | M15: =Table24[[#This Row],[Yield Strength (kN)]]/Table24[[#This Row],[Mass (g)]] -> 0.054352304
... A17: 15 | B17: Gyroid | C17: 0.25 | D17: 3 | E17: 36.8 | F17: 3.1633 | G17: 490.71 | H17: 0.0663 | I17: 1.401 | J17: =Table24[[#This Row],[Ultimate Tensile Strength (kN)]]/Table24[[#This Row],[Mass (g)]] -> 0.085959239 | K17: =Table24[[#This Row],[Modulus of Elasticity (MPa)]]/Table24[[#This Row],[Mass (g)]] -> 13.334511 | L17: =Table24[[#This Row],[Modulus of Resilience (MPa)]]/Table24[[#This Row],[Mass (g)]] -> 0.0018016304 | M17: =Table24[[#This Row],[Yield Strength (kN)]]/Table24[[#This Row],[Mass (g)]] -> 0.038070652
A18: Comparison - Infills
B19: Infill Type | C19: Average Values for Given Infill | E19: Mass (g) | F19: Ultimate Tensile Strength (kN) | G19: Modulus of Elasticity (MPA) | H19: Modulus of Resilience | I19: Yield Strength (kN) | J19: Ultimate Tensile Strength (kN) | K19: Modulus of Elasticity (MPA) | L19: Modulus of Resilience | M19: Yield Strength (kN)
B20: Grid | E20: =(SUM(E6:E7)+SUM(E12:E13))/4 -> 31.15 | F20: =(SUM(F6:F7)+SUM(F12:F13))/4 -> 2.483 | G20: =(SUM(G6:G7)+SUM(G12:G13))/4 -> 360.605 | H20: =(SUM(H6:H7)+SUM(H12:H13))/4 -> 0.113525 | I20: =(SUM(I6:I7)+SUM(I12:I13))/4 -> 1.5927 | J20: =(SUM(J6:J7)+SUM(J12:J13))/4 -> 0.080035943 | K20: =(SUM(K6:K7)+SUM(K12:K13))/4 -> 11.617332 | L20: =(SUM(L6:L7)+SUM(L12:L13))/4 -> 0.0036435241 | M20: =(SUM(M6:M7)+SUM(M12:M13))/4 -> 0.051224177
B21: Cubic | E21: =(E8+E9+E14+E15)/4 -> 30.15 | F21: =(F8+F9+F14+F15)/4 -> 2.7221 | G21: =(G8+G9+G14+G15)/4 -> 404.2625 | H21: =(H8+H9+H14+H15)/4 -> 0.098425 | I21: =(I8+I9+I14+I15)/4 -> 1.5586 | J21: =(J8+J9+J14+J15)/4 -> 0.090658602 | K21: =(K8+K9+K14+K15)/4 -> 13.470546 | L21: =(L8+L9+L14+L15)/4 -> 0.0032139899 | M21: =(M8+M9+M14+M15)/4 -> 0.0513852
B22: Gyroid | E22: =(E10+E11+E16+E17)/4 -> 30.15 | F22: =(F10+F11+F16+F17)/4 -> 2.546075 | G22: =(G10+G11+G16+G17)/4 -> 379.9775 | H22: =(H10+H11+H16+H17)/4 -> 0.087125 | I22: =(I10+I11+I16+I17)/4 -> 1.41005 | J22: =(J10+J11+J16+J17)/4 -> 0.084700026 | K22: =(K10+K11+K16+K17)/4 -> 12.593062 | L22: =(L10+L11+L16+L17)/4 -> 0.0029839995 | M22: =(M10+M11+M16+M17)/4 -> 0.047642721
A23: Comparison - Infill Density
C24: Infill Concentration | D24: Average Values for Given Infill Density | E24: Mass (g) | F24: Ultimate Tensile Strength (kN) | G24: Modulus of Elasticity (MPA) | H24: Modulus of Resilience | I24: Yield Strength (kN) | J24: Ultimate Tensile Strength (kN) | K24: Modulus of Elasticity (MPA) | L24: Modulus of Resilience | M24: Yield Strength (kN)
C25: 0 | E25: =(SUM(E4:E5))/2 -> 20.4 | F25: =(SUM(F4:F5))/2 -> 2.02645 | G25: =(SUM(G4:G5))/2 -> 283.205 | H25: =(SUM(H4:H5))/2 -> 0.0281 | I25: =(SUM(I4:I5))/2 -> 0.67105 | J25: =(SUM(J4:J5))/2 -> 0.09896155 | K25: =(SUM(K4:K5))/2 -> 13.695338 | L25: =(SUM(L4:L5))/2 -> 0.0014665938 | M25: =(SUM(M4:M5))/2 -> 0.033811725
C26: 0.1 | E26: =(E6+E8+E10+E12+E14+E16)/6 -> 26.3 | F26: =(F6+F8+F10+F12+F14+F16)/6 -> 2.3801833 | G26: =(G6+G8+G10+G12+G14+G16)/6 -> 349.585 | H26: =(H6+H8+H10+H12+H14+H16)/6 -> 0.084216667 | I26: =(I6+I8+I10+I12+I14+I16)/6 -> 1.3423167 | J26: =(J6+J8+J10+J12+J14+J16)/6 -> 0.090002313 | K26: =(K6+K8+K10+K12+K14+K16)/6 -> 13.217846 | L26: =(L6+L8+L10+L12+L14+L16)/6 -> 0.0032144015 | M26: =(M6+M8+M10+M12+M14+M16)/6 -> 0.051015023
C27: 0.25 | E27: =(E7+E9+E11+E13+E15+E17)/6 -> 34.666667 | F27: =(F7+F9+F11+F13+F15+F17)/6 -> 2.7872667 | G27: =(G7+G9+G11+G13+G15+G17)/6 -> 413.645 | H27: =(H7+H9+H11+H13+H15+H17)/6 -> 0.11516667 | I27: =(I7+I9+I11+I13+I15+I17)/6 -> 1.6985833 | J27: =(J7+J9+J11+J13+J15+J17)/6 -> 0.080260734 | K27: =(K7+K9+K11+K13+K15+K17)/6 -> 11.90278 | L27: =(L7+L9+L11+L13+L15+L17)/6 -> 0.0033466075 | M27: =(M7+M9+M11+M13+M15+M17)/6 -> 0.049153042
C28: 1 | E28: =E3 -> 73 | F28: =F3 -> 9.3463 | G28: =G3 -> 1280.88 | H28: =H3 -> 0.1056 | I28: =I3 -> 2.6982 | J28: =J3 -> 0.12803151 | K28: =K3 -> 17.546301 | L28: =L3 -> 0.0014465753 | M28: =M3 -> 0.036961644
A29: Comparison - Border #
A30: Average Values for Given Border # | D30: Border number | E30: Mass (g) | F30: Ultimate Tensile Strength (kN) | G30: Modulus of Elasticity (MPA) | H30: Modulus of Resilience | I30: Yield Strength (kN) | J30: Ultimate Tensile Strength (kN) | K30: Modulus of Elasticity (MPA) | L30: Modulus of Resilience | M30: Yield Strength (kN)
D31: 2 | E31: =(E4+SUM(E6:E11))/7 -> 26.142857 | F31: =(F4+SUM(F6:F11))/7 -> 2.1353571 | G31: =(G4+SUM(G6:G11))/7 -> 310.49714 | H31: =(H4+SUM(H6:H11))/7 -> 0.0898 | I31: =(I4+SUM(I6:I11))/7 -> 1.3062 | J31: =(J4+SUM(J6:J11))/7 -> 0.083375936 | K31: =(K4+SUM(K6:K11))/7 -> 12.036101 | L31: =(L4+SUM(L6:L11))/7 -> 0.0033158227 | M31: =(M4+SUM(M6:M11))/7 -> 0.049326945
D32: 3 | E32: =(E5+SUM(E12:E17))/7 -> 31.942857 | F32: =(F5+SUM(F12:F17))/7 -> 2.8728714 | G32: =(G5+SUM(G12:G17))/7 -> 424.61571 | H32: =(H5+SUM(H12:H17))/7 -> 0.089128571 | I32: =(I5+SUM(I12:I17))/7 -> 1.4920143 | J32: =(J5+SUM(J12:J17))/7 -> 0.090838547 | K32: =(K5+SUM(K12:K17))/7 -> 13.408818 | L32: =(L5+SUM(L12:L17))/7 -> 0.0027269261 | M32: =(M5+SUM(M12:M17))/7 -> 0.04619189

Sheet PETG
A1: Original Data | J1: Specific (divided by mass)
A2: Index Value | B2: Infill Type | C2: Infill Concentration | D2: Border number | E2: Mass (g) | F2: Ultimate Tensile Strength (kN) | G2: Modulus of Elasticity (MPa) | H2: Modulus of Resilience (MPa) | I2: Yield Strength (kN) | J2: Specific UTS (kN/g) | K2: Specific Modulus of Elasticity (MPa/g) | L2: Specific Modulus of Resilience (MPa/g) | M2: Specifc Yield Strength (kN)
A3: 1 | B3: N/a | C3: 1 | D3: Inf | E3: 74.6 | F3: 9.6693 | G3: 713.07 | H3: 0.2849 | I3: 3.56 | J3: =Table245[[#This Row],[Ultimate Tensile Strength (kN)]]/Table245[[#This Row],[Mass (g)]] -> 0.12961528 | K3: =Table245[[#This Row],[Modulus of Elasticity (MPa)]]/Table245[[#This Row],[Mass (g)]] -> 9.5585791 | L3: =Table245[[#This Row],[Modulus of Resilience (MPa)]]/Table245[[#This Row],[Mass (g)]] -> 0.0038190349 | M3: =Table245[[#This Row],[Yield Strength (kN)]]/Table245[[#This Row],[Mass (g)]] -> 0.04772118
A4: 2 | B4: N/a | C4: 0 | D4: 2 | E4: 18 | F4: 1.5726 | G4: 121.17 | H4: 0.0742 | I4: 0.7568 | J4: =Table245[[#This Row],[Ultimate Tensile Strength (kN)]]/Table245[[#This Row],[Mass (g)]] -> 0.087366667 | K4: =Table245[[#This Row],[Modulus of Elasticity (MPa)]]/Table245[[#This Row],[Mass (g)]] -> 6.7316667 | L4: =Table245[[#This Row],[Modulus of Resilience (MPa)]]/Table245[[#This Row],[Mass (g)]] -> 0.0041222222 | M4: =Table245[[#This Row],[Yield Strength (kN)]]/Table245[[#This Row],[Mass (g)]] -> 0.042044444
A5: 3 | B5: N/a | C5: 0 | D5: 3 | E5: 26.7 | F5: 2.6493 | G5: 228.77 | H5: 0.0259 | I5: 0.598 | J5: =Table245[[#This Row],[Ultimate Tensile Strength (kN)]]/Table245[[#This Row],[Mass (g)]] -> 0.099224719 | K5: =Table245[[#This Row],[Modulus of Elasticity (MPa)]]/Table245[[#This Row],[Mass (g)]] -> 8.5681648 | L5: =Table245[[#This Row],[Modulus of Resilience (MPa)]]/Table245[[#This Row],[Mass (g)]] -> 0.00097003745 | M5: =Table245[[#This Row],[Yield Strength (kN)]]/Table245[[#This Row],[Mass (g)]] -> 0.022397004
A6: 4 | B6: Grid | C6: 0.1 | D6: 2 | E6: 24.4 | F6: 2.0192 | G6: 176.33 | H6: 0.0994 | I6: 1.0671 | J6: =Table245[[#This Row],[Ultimate Tensile Strength (kN)]]/Table245[[#This Row],[Mass (g)]] -> 0.082754098 | K6: =Table245[[#This Row],[Modulus of Elasticity (MPa)]]/Table245[[#This Row],[Mass (g)]] -> 7.2266393 | L6: =Table245[[#This Row],[Modulus of Resilience (MPa)]]/Table245[[#This Row],[Mass (g)]] -> 0.0040737705 | M6: =Table245[[#This Row],[Yield Strength (kN)]]/Table245[[#This Row],[Mass (g)]] -> 0.043733607
A7: 5 | B7: Grid | C7: 0.25 | D7: 2 | E7: 35.5 | F7: 2.3 | G7: 198.2 | H7: 0.2044 | I7: 1.5927 | J7: =Table245[[#This Row],[Ultimate Tensile Strength (kN)]]/Table245[[#This Row],[Mass (g)]] -> 0.064788732 | K7: =Table245[[#This Row],[Modulus of Elasticity (MPa)]]/Table245[[#This Row],[Mass (g)]] -> 5.5830986 | L7: =Table245[[#This Row],[Modulus of Resilience (MPa)]]/Table245[[#This Row],[Mass (g)]] -> 0.0057577465 | M7: =Table245[[#This Row],[Yield Strength (kN)]]/Table245[[#This Row],[Mass (g)]] -> 0.044864789
A8: 6 | B8: Cubic | C8: 0.1 | D8: 2 | E8: 22.5 | F8: 1.7901 | G8: 162.5 | H8: 0.0752 | I8: 0.8549 | J8: =Table245[[#This Row],[Ultimate Tensile Strength (kN)]]/Table245[[#This Row],[Mass (g)]] -> 0.07956 | K8: =Table245[[#This Row],[Modulus of Elasticity (MPa)]]/Table245[[#This Row],[Mass (g)]] -> 7.2222222 | L8: =Table245[[#This Row],[Modulus of Resilience (MPa)]]/Table245[[#This Row],[Mass (g)]] -> 0.0033422222 | M8: =Table245[[#This Row],[Yield Strength (kN)]]/Table245[[#This Row],[Mass (g)]] -> 0.037995556
A9: 7 | B9: Cubic | C9: 0.25 | D9: 2 | E9: 30.8 | F9: 2.2188 | G9: 196.94 | H9: 0.1185 | I9: 1.2204 | J9: =Table245[[#This Row],[Ultimate Tensile Strength (kN)]]/Table245[[#This Row],[Mass (g)]] -> 0.072038961 | K9: =Table245[[#This Row],[Modulus of Elasticity (MPa)]]/Table245[[#This Row],[Mass (g)]] -> 6.3941558 | L9: =Table245[[#This Row],[Modulus of Resilience (MPa)]]/Table245[[#This Row],[Mass (g)]] -> 0.0038474026 | M9: =Table245[[#This Row],[Yield Strength (kN)]]/Table245[[#This Row],[Mass (g)]] -> 0.039623377
A10: 8 | B10: Gyroid | C10: 0.1 | D10: 2 | E10: 22.6 | F10: 1.7519 | G10: 158.37 | H10: 0.0401 | I10: 0.6326 | J10: =Table245[[#This Row],[Ultimate Tensile Strength (kN)]]/Table245[[#This Row],[Mass (g)]] -> 0.077517699 | K10: =Table245[[#This Row],[Modulus of Elasticity (MPa)]]/Table245[[#This Row],[Mass (g)]] -> 7.0075221 | L10: =Table245[[#This Row],[Modulus of Resilience (MPa)]]/Table245[[#This Row],[Mass (g)]] -> 0.0017743363 | M10: =Table245[[#This Row],[Yield Strength (kN)]]/Table245[[#This Row],[Mass (g)]] -> 0.02799115
A11: 9 | B11: Gyroid | C11: 0.25 | D11: 2 | E11: 30.5 | F11: 2.1164 | G11: 183.51 | H11: 0.1204 | I11: 1.1699 | J11: =Table245[[#This Row],[Ultimate Tensile Strength (kN)]]/Table245[[#This Row],[Mass (g)]] -> 0.069390164 | K11: =Table245[[#This Row],[Modulus of Elasticity (MPa)]]/Table245[[#This Row],[Mass (g)]] -> 6.0167213 | L11: =Table245[[#This Row],[Modulus of Resilience (MPa)]]/Table245[[#This Row],[Mass (g)]] -> 0.003947541 | M11: =Table245[[#This Row],[Yield Strength (kN)]]/Table245[[#This Row],[Mass (g)]] -> 0.038357377
A12: 10 | B12: Grid | C12: 0.1 | D12: 3 | E12: 29.2 | F12: 2.3268 | G12: 216.39 | H12: 0.0885 | I12: 1.1034 | J12: =Table245[[#This Row],[Ultimate Tensile Strength (kN)]]/Table245[[#This Row],[Mass (g)]] -> 0.079684932 | K12: =Table245[[#This Row],[Modulus of Elasticity (MPa)]]/Table245[[#This Row],[Mass (g)]] -> 7.4106164 | L12: =Table245[[#This Row],[Modulus of Resilience (MPa)]]/Table245[[#This Row],[Mass (g)]] -> 0.0030308219 | M12: =Table245[[#This Row],[Yield Strength (kN)]]/Table245[[#This Row],[Mass (g)]] -> 0.037787671
A13: 11 | B13: Grid | C13: 0.25 | D13: 3 | E13: 36.1 | F13: 2.5102 | G13: 222.88 | H13: 0.1659 | I13: 1.4642 | J13: =Table245[[#This Row],[Ultimate Tensile Strength (kN)]]/Table245[[#This Row],[Mass (g)]] -> 0.069534626 | K13: =Table245[[#This Row],[Modulus of Elasticity (MPa)]]/Table245[[#This Row],[Mass (g)]] -> 6.1739612 | L13: =Table245[[#This Row],[Modulus of Resilience (MPa)]]/Table245[[#This Row],[Mass (g)]] -> 0.0045955679 | M13: =Table245[[#This Row],[Yield Strength (kN)]]/Table245[[#This Row],[Mass (g)]] -> 0.040559557
A14: 12 | B14: Cubic | C14: 0.1 | D14: 3 | E14: 28.9 | F14: 2.5668 | G14: 234.1 | H14: 0.0723 | I14: 1.0249 | J14: =Table245[[#This Row],[Ultimate Tensile Strength (kN)]]/Table245[[#This Row],[Mass (g)]] -> 0.088816609 | K14: =Table245[[#This Row],[Modulus of Elasticity (MPa)]]/Table245[[#This Row],[Mass (g)]] -> 8.100346 | L14: =Table245[[#This Row],[Modulus of Resilience (MPa)]]/Table245[[#This Row],[Mass (g)]] -> 0.0025017301 | M14: =Table245[[#This Row],[Yield Strength (kN)]]/Table245[[#This Row],[Mass (g)]] -> 0.035463668
A15: 13 | B15: Cubic | C15: 0.25 | D15: 3 | E15: 36.2 | F15: 2.9684 | G15: 297.6 | H15: 0.0455 | I15: 0.9262 | J15: =Table245[[#This Row],[Ultimate Tensile Strength (kN)]]/Table245[[#This Row],[Mass (g)]] -> 0.082 | K15: =Table245[[#This Row],[Modulus of Elasticity (MPa)]]/Table245[[#This Row],[Mass (g)]] -> 8.2209945 | L15: =Table245[[#This Row],[Modulus of Resilience (MPa)]]/Table245[[#This Row],[Mass (g)]] -> 0.0012569061 | M15: =Table245[[#This Row],[Yield Strength (kN)]]/Table245[[#This Row],[Mass (g)]] -> 0.025585635
... A17: 15 | B17: Gyroid | C17: 0.25 | D17: 3 | E17: 35.9 | F17: 2.6422 | G17: 252.96 | H17: 0.0794 | I17: 1.1319 | J17: =Table245[[#This Row],[Ultimate Tensile Strength (kN)]]/Table245[[#This Row],[Mass (g)]] -> 0.073598886 | K17: =Table245[[#This Row],[Modulus of Elasticity (MPa)]]/Table245[[#This Row],[Mass (g)]] -> 7.0462396 | L17: =Table245[[#This Row],[Modulus of Resilience (MPa)]]/Table245[[#This Row],[Mass (g)]] -> 0.0022116992 | M17: =Table245[[#This Row],[Yield Strength (kN)]]/Table245[[#This Row],[Mass (g)]] -> 0.031529248
A18: Comparison - Infills
B19: Infill Type | C19: Average Values for Given Infill Style | E19: Mass (g) | F19: Ultimate Tensile Strength (kN) | G19: Modulus of Elasticity (MPA) | H19: Modulus of Resilience | I19: Yield Strength (kN) | J19: Specific UTS (kN/g) | K19: Specific Modulus of Elasticity (MPa/g) | L19: Specific Modulus of Resilience (MPa/g) | M19: Specifc Yield Strength (kN)
B20: Grid | E20: =(SUM(E6:E7)+SUM(E12:E13))/4 -> 31.3 | F20: =(SUM(F6:F7)+SUM(F12:F13))/4 -> 2.28905 | G20: =(SUM(G6:G7)+SUM(G12:G13))/4 -> 203.45 | H20: =(SUM(H6:H7)+SUM(H12:H13))/4 -> 0.13955 | I20: =(SUM(I6:I7)+SUM(I12:I13))/4 -> 1.30685 | J20: =(SUM(J6:J7)+SUM(J12:J13))/4 -> 0.074190597 | K20: =(SUM(K6:K7)+SUM(K12:K13))/4 -> 6.5985789 | L20: =(SUM(L6:L7)+SUM(L12:L13))/4 -> 0.0043644767 | M20: =(SUM(M6:M7)+SUM(M12:M13))/4 -> 0.041736406
B21: Cubic | E21: =(E8+E9+E14+E15)/4 -> 29.6 | F21: =(F8+F9+F14+F15)/4 -> 2.386025 | G21: =(G8+G9+G14+G15)/4 -> 222.785 | H21: =(H8+H9+H14+H15)/4 -> 0.077875 | I21: =(I8+I9+I14+I15)/4 -> 1.0066 | J21: =(J8+J9+J14+J15)/4 -> 0.080603893 | K21: =(K8+K9+K14+K15)/4 -> 7.4844296 | L21: =(L8+L9+L14+L15)/4 -> 0.0027370653 | M21: =(M8+M9+M14+M15)/4 -> 0.034667059
B22: Gyroid | E22: =(E10+E11+E16+E17)/4 -> 29.55 | F22: =(F10+F11+F16+F17)/4 -> 2.228475 | G22: =(G10+G11+G16+G17)/4 -> 208.6525 | H22: =(H10+H11+H16+H17)/4 -> 0.07135 | I22: =(I10+I11+I16+I17)/4 -> 0.938675 | J22: =(J10+J11+J16+J17)/4 -> 0.075703742 | K22: =(K10+K11+K16+K17)/4 -> 7.0704461 | L22: =(L10+L11+L16+L17)/4 -> 0.0023729489 | M22: =(M10+M11+M16+M17)/4 -> 0.03149256
A23: Comparison - Infill Density
C24: Infill Concentration | D24: Average Values for Given Infill Density | E24: Mass (g) | F24: Ultimate Tensile Strength (kN) | G24: Modulus of Elasticity (MPA) | H24: Modulus of Resilience | I24: Yield Strength (kN) | J24: Specific UTS (kN/g) | K24: Specific Modulus of Elasticity (MPa/g) | L24: Specific Modulus of Resilience (MPa/g) | M24: Specifc Yield Strength (kN)
C25: 0 | E25: =(SUM(E4:E5))/2 -> 22.35 | F25: =(SUM(F4:F5))/2 -> 2.11095 | G25: =(SUM(G4:G5))/2 -> 174.97 | H25: =(SUM(H4:H5))/2 -> 0.05005 | I25: =(SUM(I4:I5))/2 -> 0.6774 | J25: =(SUM(J4:J5))/2 -> 0.093295693 | K25: =(SUM(K4:K5))/2 -> 7.6499157 | L25: =(SUM(L4:L5))/2 -> 0.0025461298 | M25: =(SUM(M4:M5))/2 -> 0.032220724
C26: 0.1 | E26: =(E6+E8+E10+E12+E14+E16)/6 -> 26.133333 | F26: =(F6+F8+F10+F12+F14+F16)/6 -> 2.1430333 | G26: =(G6+G8+G10+G12+G14+G16)/6 -> 197.91 | H26: =(H6+H8+H10+H12+H14+H16)/6 -> 0.070166667 | I26: =(I6+I8+I10+I12+I14+I16)/6 -> 0.9172 | J26: =(J6+J8+J10+J12+J14+J16)/6 -> 0.081773593 | K26: =(K6+K8+K10+K12+K14+K16)/6 -> 7.5297746 | L26: =(L6+L8+L10+L12+L14+L16)/6 -> 0.0027135167 | M26: =(M6+M8+M10+M12+M14+M16)/6 -> 0.035177353
C27: 0.25 | E27: =(E7+E9+E11+E13+E15+E17)/6 -> 34.166667 | F27: =(F7+F9+F11+F13+F15+F17)/6 -> 2.4593333 | G27: =(G7+G9+G11+G13+G15+G17)/6 -> 225.34833 | H27: =(H7+H9+H11+H13+H15+H17)/6 -> 0.12235 | I27: =(I7+I9+I11+I13+I15+I17)/6 -> 1.2508833 | J27: =(J7+J9+J11+J13+J15+J17)/6 -> 0.071891895 | K27: =(K7+K9+K11+K13+K15+K17)/6 -> 6.5725285 | L27: =(L7+L9+L11+L13+L15+L17)/6 -> 0.0036028105 | M27: =(M7+M9+M11+M13+M15+M17)/6 -> 0.03675333
C28: 1 | E28: =E3 -> 74.6 | F28: =F3 -> 9.6693 | G28: =G3 -> 713.07 | H28: =H3 -> 0.2849 | I28: =I3 -> 3.56 | J28: =J3 -> 0.12961528 | K28: =K3 -> 9.5585791 | L28: =L3 -> 0.0038190349 | M28: =M3 -> 0.04772118
A29: Comparison - Border #
A30: Average Values for Given Border # | D30: Border number | E30: Mass (g) | F30: Ultimate Tensile Strength (kN) | G30: Modulus of Elasticity (MPA) | H30: Modulus of Resilience | I30: Yield Strength (kN) | J30: Specific UTS (kN/g) | K30: Specific Modulus of Elasticity (MPa/g) | L30: Specific Modulus of Resilience (MPa/g) | M30: Specifc Yield Strength (kN)
D31: 2 | E31: =(E4+SUM(E6:E11))/7 -> 26.328571 | F31: =(F4+SUM(F6:F11))/7 -> 1.967 | G31: =(G4+SUM(G6:G11))/7 -> 171.00286 | H31: =(H4+SUM(H6:H11))/7 -> 0.1046 | I31: =(I4+SUM(I6:I11))/7 -> 1.0420571 | J31: =(J4+SUM(J6:J11))/7 -> 0.076202332 | K31: =(K4+SUM(K6:K11))/7 -> 6.5974323 | L31: =(L4+SUM(L6:L11))/7 -> 0.0038378916 | M31: =(M4+SUM(M6:M11))/7 -> 0.039230043
D32: 3 | E32: =(E5+SUM(E12:E17))/7 -> 31.742857 | F32: =(F5+SUM(F12:F17))/7 -> 2.5810143 | G32: =(G5+SUM(G12:G17))/7 -> 241.78143 | H32: =(H5+SUM(H12:H17))/7 -> 0.074714286 | I32: =(I5+SUM(I12:I17))/7 -> 1.0098429 | J32: =(J5+SUM(J12:J17))/7 -> 0.082166856 | K32: =(K5+SUM(K12:K17))/7 -> 7.6759463 | L32: =(L5+SUM(L12:L17))/7 -> 0.0023035688 | M32: =(M5+SUM(M12:M17))/7 -> 0.03163075

Sheet Index Chart
A2: Index Value | B2: Infill Type | C2: Infill Concentration | D2: Index Value | E2: Infill Type | F2: Infill Concentration | G2: Index Value | H2: Infill Type | I2: Infill Concentration
A3: 1 | B3: N/a | C3: 1 | D3: 6 | E3: Cubic | F3: 0.1 | G3: 11 | H3: Grid | I3: 0.25
A4: 2 | B4: N/a | C4: 0 | D4: 7 | E4: Cubic | F4: 0.25 | G4: 12 | H4: Cubic | I4: 0.1
A5: 3 | B5: N/a | C5: 0 | D5: 8 | E5: Gyroid | F5: 0.1 | G5: 13 | H5: Cubic | I5: 0.25
A6: 4 | B6: Grid | C6: 0.1 | D6: 9 | E6: Gyroid | F6: 0.25 | G6: 14 | H6: Gyroid | I6: 0.1
A7: 5 | B7: Grid | C7: 0.25 | D7: 10 | E7: Grid | F7: 0.1 | G7: 15 | H7: Gyroid | I7: 0.25

Sheet Infill Style Comparison - UTS
A2: Grid | E2: Cubic | I2: Gyroid
A3: Material | B3: Index | C3: Ultimate Tensile Strength (kN) | E3: Material | F3: Index | G3: Ultimate Tensile Strength (kN) | I3: Material | J3: Index | K3: Ultimate Tensile Strength (kN) | M3: Grid | N3: Cubic | O3: Gyroid
A4: ABS | B4: 4 | C4: =ABS!F6 -> 1.335 | E4: ABS | F4: 6 | G4: =D38 -> 1.4693 | I4: ABS | J4: 8 | K4: =D40 -> 1.4343 | M4: =C4 -> 1.335 | N4: =G4 -> 1.4693 | O4: =K4 -> 1.4343
A5: ABS | B5: 5 | C5: =ABS!F7 -> 1.445 | E5: ABS | F5: 7 | G5: =D39 -> 1.8183 | I5: ABS | J5: 9 | K5: =D41 -> 1.5629 | M5: =C5 -> 1.445 | N5: =G5 -> 1.8183 | O5: =K5 -> 1.5629
A6: ABS | B6: 10 | C6: =ABS!F12 -> 1.8508 | E6: ABS | F6: 12 | G6: =D44 -> 2.0702 | I6: ABS | J6: 14 | K6: =D46 -> 1.8688 | M6: =C6 -> 1.8508 | N6: =G6 -> 2.0702 | O6: =K6 -> 1.8688
A7: ABS | B7: 11 | C7: =ABS!F13 -> 2.1374 | E7: ABS | F7: 13 | G7: =D45 -> 2.3705 | I7: ABS | J7: 15 | K7: =D47 -> 2.1361 | M7: =C7 -> 2.1374 | N7: =G7 -> 2.3705 | O7: =K7 -> 2.1361
A8: PLA | B8: 4 | C8: =PLA!F6 -> 1.7476 | E8: PLA | F8: 6 | G8: =I38 -> 2.1302 | I8: PLA | J8: 8 | K8: =I40 -> 2.0438 | M8: =C8 -> 1.7476 | N8: =G8 -> 2.1302 | O8: =K8 -> 2.0438
A9: PLA | B9: 5 | C9: =PLA!F7 -> 2.4642 | E9: PLA | F9: 7 | G9: =I39 -> 2.6031 | I9: PLA | J9: 9 | K9: =I41 -> 2.3404 | M9: =C9 -> 2.4642 | N9: =G9 -> 2.6031 | O9: =K9 -> 2.3404
A10: PLA | B10: 10 | C10: =PLA!F12 -> 2.8334 | E10: PLA | F10: 12 | G10: =I44 -> 2.8893 | I10: PLA | J10: 14 | K10: =I46 -> 2.6368 | M10: =C10 -> 2.8334 | N10: =G10 -> 2.8893 | O10: =K10 -> 2.6368
A11: PLA | B11: 11 | C11: =PLA!F13 -> 2.8868 | E11: PLA | F11: 13 | G11: =I45 -> 3.2658 | I11: PLA | J11: 15 | K11: =I47 -> 3.1633 | M11: =C11 -> 2.8868 | N11: =G11 -> 3.2658 | O11: =K11 -> 3.1633
A12: PETG | B12: 4 | C12: =PETG!F6 -> 2.0192 | E12: PETG | F12: 6 | G12: =N38 -> 1.7901 | I12: PETG | J12: 8 | K12: =N40 -> 1.7519 | M12: =C12 -> 2.0192 | N12: =G12 -> 1.7901 | O12: =K12 -> 1.7519
A13: PETG | B13: 5 | C13: =PETG!F7 -> 2.3 | E13: PETG | F13: 7 | G13: =N39 -> 2.2188 | I13: PETG | J13: 9 | K13: =N41 -> 2.1164 | M13: =C13 -> 2.3 | N13: =G13 -> 2.2188 | O13: =K13 -> 2.1164
A14: PETG | B14: 10 | C14: =PETG!F12 -> 2.3268 | E14: PETG | F14: 12 | G14: =N44 -> 2.5668 | I14: PETG | J14: 14 | K14: =N46 -> 2.4034 | M14: =C14 -> 2.3268 | N14: =G14 -> 2.5668 | O14: =K14 -> 2.4034
A15: PETG | B15: 11 | C15: =PETG!F13 -> 2.5102 | E15: PETG | F15: 13 | G15: =N45 -> 2.9684 | I15: PETG | J15: 15 | K15: =N47 -> 2.6422 | M15: =C15 -> 2.5102 | N15: =G15 -> 2.9684 | O15: =K15 -> 2.6422
A16: Infill | B16: Average Ultimate Strength
A17: Grid | B17: =AVERAGE(C4:C15) -> 2.1547
A18: Cubic | B18: =AVERAGE(G4:G15) -> 2.3467333
A19: Gyroid | B19: =AVERAGE(K4:K15) -> 2.175025
A21: Max Difference: | B21: =(1-B17/B18) -> 0.081830062
A34: ABS | F34: PLA | K34: PETG
A35: Index Value | B35: Infill Type | C35: Mass (g) | D35: Ultimate Tensile Strength (kN) | F35: Index Value | G35: Infill Type | H35: Mass (g) | I35: Ultimate Tensile Strength (kN) | K35: Index Value | L35: Infill Type | M35: Mass (g) | N35: Ultimate Tensile Strength (kN)
A36: 4 | B36: Grid | C36: 19.2 | D36: 1.335 | F36: 4 | G36: Grid | H36: 23 | I36: 1.7476 | K36: 4 | L36: Grid | M36: 24.4 | N36: 2.0192
A37: 5 | B37: Grid | C37: 26 | D37: 1.445 | F37: 5 | G37: Grid | H37: 35.1 | I37: 2.4642 | K37: 5 | L37: Grid | M37: 35.5 | N37: 2.3
A38: 6 | B38: Cubic | C38: 19 | D38: 1.4693 | F38: 6 | G38: Cubic | H38: 22.9 | I38: 2.1302 | K38: 6 | L38: Cubic | M38: 22.5 | N38: 1.7901
A39: 7 | B39: Cubic | C39: 26.1 | D39: 1.8183 | F39: 7 | G39: Cubic | H39: 31.3 | I39: 2.6031 | K39: 7 | L39: Cubic | M39: 30.8 | N39: 2.2188
A40: 8 | B40: Gyroid | C40: 19 | D40: 1.4343 | F40: 8 | G40: Gyroid | H40: 23 | I40: 2.0438 | K40: 8 | L40: Gyroid | M40: 22.6 | N40: 1.7519
A41: 9 | B41: Gyroid | C41: 25.6 | D41: 1.5629 | F41: 9 | G41: Gyroid | H41: 31 | I41: 2.3404 | K41: 9 | L41: Gyroid | M41: 30.5 | N41: 2.1164
A42: 10 | B42: Grid | C42: 24.5 | D42: 1.8508 | F42: 10 | G42: Grid | H42: 29.6 | I42: 2.8334 | K42: 10 | L42: Grid | M42: 29.2 | N42: 2.3268
A43: 11 | B43: Grid | C43: 30.8 | D43: 2.1374 | F43: 11 | G43: Grid | H43: 36.9 | I43: 2.8868 | K43: 11 | L43: Grid | M43: 36.1 | N43: 2.5102
A44: 12 | B44: Cubic | C44: 24.6 | D44: 2.0702 | F44: 12 | G44: Cubic | H44: 29.5 | I44: 2.8893 | K44: 12 | L44: Cubic | M44: 28.9 | N44: 2.5668
A45: 13 | B45: Cubic | C45: 30.8 | D45: 2.3705 | F45: 13 | G45: Cubic | H45: 36.9 | I45: 3.2658 | K45: 13 | L45: Cubic | M45: 36.2 | N45: 2.9684
A46: 14 | B46: Gyroid | C46: 24.6 | D46: 1.8688 | F46: 14 | G46: Gyroid | H46: 29.8 | I46: 2.6368 | K46: 14 | L46: Gyroid | M46: 29.2 | N46: 2.4034
A47: 15 | B47: Gyroid | C47: 30.4 | D47: 2.1361 | F47: 15 | G47: Gyroid | H47: 36.8 | I47: 3.1633 | K47: 15 | L47: Gyroid | M47: 35.9 | N47: 2.6422

Sheet Infill Style Comparison - MoE
A2: Grid | E2: Cubic | I2: Gyroid
A3: Material | B3: Index | C3: Ultimate Tensile Strength (kN) | E3: Material | F3: Index | G3: Ultimate Tensile Strength (kN) | I3: Material | J3: Index | K3: Ultimate Tensile Strength (kN) | M3: Grid | N3: Cubic | O3: Gyroid
A4: ABS | B4: 4 | C4: =D36 -> 205.66 | E4: ABS | F4: 6 | G4: =D38 -> 227.06 | I4: ABS | J4: 8 | K4: =D40 -> 190.34 | M4: =C4 -> 205.66 | N4: =G4 -> 227.06 | O4: =K4 -> 190.34
A5: ABS | B5: 5 | C5: =D37 -> 201.67 | E5: ABS | F5: 7 | G5: =D39 -> 250.75 | I5: ABS | J5: 9 | K5: =D41 -> 238.64 | M5: =C5 -> 201.67 | N5: =G5 -> 250.75 | O5: =K5 -> 238.64
A6: ABS | B6: 10 | C6: =D42 -> 252.92 | E6: ABS | F6: 12 | G6: =D44 -> 318.51 | I6: ABS | J6: 14 | K6: =D46 -> 277.42 | M6: =C6 -> 252.92 | N6: =G6 -> 318.51 | O6: =K6 -> 277.42
A7: ABS | B7: 11 | C7: =D43 -> 276.22 | E7: ABS | F7: 13 | G7: =D45 -> 326.7 | I7: ABS | J7: 15 | K7: =D47 -> 285.92 | M7: =C7 -> 276.22 | N7: =G7 -> 326.7 | O7: =K7 -> 285.92
A8: PLA | B8: 4 | C8: =I36 -> 254.67 | E8: PLA | F8: 6 | G8: =I38 -> 319.06 | I8: PLA | J8: 8 | K8: =I40 -> 295.55 | M8: =C8 -> 254.67 | N8: =G8 -> 319.06 | O8: =K8 -> 295.55
A9: PLA | B9: 5 | C9: =I37 -> 369.98 | E9: PLA | F9: 7 | G9: =I39 -> 390.65 | I9: PLA | J9: 9 | K9: =I41 -> 332.1 | M9: =C9 -> 369.98 | N9: =G9 -> 390.65 | O9: =K9 -> 332.1
A10: PLA | B10: 10 | C10: =I42 -> 403.11 | E10: PLA | F10: 12 | G10: =I44 -> 423.57 | I10: PLA | J10: 14 | K10: =I46 -> 401.55 | M10: =C10 -> 403.11 | N10: =G10 -> 423.57 | O10: =K10 -> 401.55
A11: PLA | B11: 11 | C11: =I43 -> 414.66 | E11: PLA | F11: 13 | G11: =I45 -> 483.77 | I11: PLA | J11: 15 | K11: =I47 -> 490.71 | M11: =C11 -> 414.66 | N11: =G11 -> 483.77 | O11: =K11 -> 490.71
A12: PETG | B12: 4 | C12: =N36 -> 176.33 | E12: PETG | F12: 6 | G12: =N38 -> 162.5 | I12: PETG | J12: 8 | K12: =N40 -> 158.37 | M12: =C12 -> 176.33 | N12: =G12 -> 162.5 | O12: =K12 -> 158.37
A13: PETG | B13: 5 | C13: =N37 -> 198.2 | E13: PETG | F13: 7 | G13: =N39 -> 196.94 | I13: PETG | J13: 9 | K13: =N41 -> 183.51 | M13: =C13 -> 198.2 | N13: =G13 -> 196.94 | O13: =K13 -> 183.51
A14: PETG | B14: 10 | C14: =N42 -> 216.39 | E14: PETG | F14: 12 | G14: =N44 -> 234.1 | I14: PETG | J14: 14 | K14: =N46 -> 239.77 | M14: =C14 -> 216.39 | N14: =G14 -> 234.1 | O14: =K14 -> 239.77
A15: PETG | B15: 11 | C15: =N43 -> 222.88 | E15: PETG | F15: 13 | G15: =N45 -> 297.6 | I15: PETG | J15: 15 | K15: =N47 -> 252.96 | M15: =C15 -> 222.88 | N15: =G15 -> 297.6 | O15: =K15 -> 252.96
A16: Infill | B16: Average Ultimate Strength
A17: Grid | B17: =AVERAGE(C4:C15) -> 266.0575
A18: Cubic | B18: =AVERAGE(G4:G15) -> 302.60083
A19: Gyroid | B19: =AVERAGE(K4:K15) -> 278.90333
A21: Max Difference: | B21: =(1-B17/B18) -> 0.12076415
A34: ABS | F34: PLA | K34: PETG
A35: Index Value | B35: Infill Type | C35: Mass (g) | D35: Modulus of Elasticity (MPa) | F35: Index Value | G35: Infill Type | H35: Mass (g) | I35: Modulus of Elasticity (MPa) | K35: Index Value | L35: Infill Type | M35: Mass (g) | N35: Modulus of Elasticity (MPa)
A36: 4 | B36: Grid | C36: 19.2 | D36: 205.66 | F36: 4 | G36: Grid | H36: 23 | I36: 254.67 | K36: 4 | L36: Grid | M36: 24.4 | N36: 176.33
A37: 5 | B37: Grid | C37: 26 | D37: 201.67 | F37: 5 | G37: Grid | H37: 35.1 | I37: 369.98 | K37: 5 | L37: Grid | M37: 35.5 | N37: 198.2
A38: 6 | B38: Cubic | C38: 19 | D38: 227.06 | F38: 6 | G38: Cubic | H38: 22.9 | I38: 319.06 | K38: 6 | L38: Cubic | M38: 22.5 | N38: 162.5
A39: 7 | B39: Cubic | C39: 26.1 | D39: 250.75 | F39: 7 | G39: Cubic | H39: 31.3 | I39: 390.65 | K39: 7 | L39: Cubic | M39: 30.8 | N39: 196.94
A40: 8 | B40: Gyroid | C40: 19 | D40: 190.34 | F40: 8 | G40: Gyroid | H40: 23 | I40: 295.55 | K40: 8 | L40: Gyroid | M40: 22.6 | N40: 158.37
A41: 9 | B41: Gyroid | C41: 25.6 | D41: 238.64 | F41: 9 | G41: Gyroid | H41: 31 | I41: 332.1 | K41: 9 | L41: Gyroid | M41: 30.5 | N41: 183.51
A42: 10 | B42: Grid | C42: 24.5 | D42: 252.92 | F42: 10 | G42: Grid | H42: 29.6 | I42: 403.11 | K42: 10 | L42: Grid | M42: 29.2 | N42: 216.39
A43: 11 | B43: Grid | C43: 30.8 | D43: 276.22 | F43: 11 | G43: Grid | H43: 36.9 | I43: 414.66 | K43: 11 | L43: Grid | M43: 36.1 | N43: 222.88
A44: 12 | B44: Cubic | C44: 24.6 | D44: 318.51 | F44: 12 | G44: Cubic | H44: 29.5 | I44: 423.57 | K44: 12 | L44: Cubic | M44: 28.9 | N44: 234.1
A45: 13 | B45: Cubic | C45: 30.8 | D45: 326.7 | F45: 13 | G45: Cubic | H45: 36.9 | I45: 483.77 | K45: 13 | L45: Cubic | M45: 36.2 | N45: 297.6
A46: 14 | B46: Gyroid | C46: 24.6 | D46: 277.42 | F46: 14 | G46: Gyroid | H46: 29.8 | I46: 401.55 | K46: 14 | L46: Gyroid | M46: 29.2 | N46: 239.77
A47: 15 | B47: Gyroid | C47: 30.4 | D47: 285.92 | F47: 15 | G47: Gyroid | H47: 36.8 | I47: 490.71 | K47: 15 | L47: Gyroid | M47: 35.9 | N47: 252.96

Sheet Infill Style Comparison - MoR
A2: ABS | E2: PLA | I2: PETG
A3: Material | B3: Index | C3: Modulus of Resilience (MPa) | E3: Material | F3: Index | G3: Modulus of Resilience (MPa) | I3: Material | J3: Index | K3: Modulus of Resilience (MPa) | M3: Grid | N3: Cubic | O3: Gyroid
A4: ABS | B4: 4 | C4: =D36 -> 0.0207 | E4: ABS | F4: 6 | G4: =D38 -> 0.0161 | I4: ABS | J4: 8 | K4: =D40 -> 0.0587 | M4: =C4 -> 0.0207 | N4: =G4 -> 0.0161 | O4: =K4 -> 0.0587
A5: ABS | B5: 5 | C5: =D37 -> 0.061 | E5: ABS | F5: 7 | G5: =D39 -> 0.0893 | I5: ABS | J5: 9 | K5: =D41 -> 0.0256 | M5: =C5 -> 0.061 | N5: =G5 -> 0.0893 | O5: =K5 -> 0.0256
A6: ABS | B6: 10 | C6: =D38 -> 0.0161 | E6: ABS | F6: 12 | G6: =D44 -> 0.0202 | I6: ABS | J6: 14 | K6: =D46 -> 0.0392 | M6: =C6 -> 0.0161 | N6: =G6 -> 0.0202 | O6: =K6 -> 0.0392
A7: ABS | B7: 11 | C7: =D39 -> 0.0893 | E7: ABS | F7: 13 | G7: =D45 -> 0.1067 | I7: ABS | J7: 15 | K7: =D47 -> 0.0969 | M7: =C7 -> 0.0893 | N7: =G7 -> 0.1067 | O7: =K7 -> 0.0969
A8: PLA | B8: 4 | C8: =D40 -> 0.0587 | E8: PLA | F8: 6 | G8: =I38 -> 0.0673 | I8: PLA | J8: 8 | K8: =I40 -> 0.0814 | M8: =C8 -> 0.0587 | N8: =G8 -> 0.0673 | O8: =K8 -> 0.0814
A9: PLA | B9: 5 | C9: =D41 -> 0.0256 | E9: PLA | F9: 7 | G9: =I39 -> 0.1223 | I9: PLA | J9: 9 | K9: =I41 -> 0.1101 | M9: =C9 -> 0.0256 | N9: =G9 -> 0.1223 | O9: =K9 -> 0.1101
A10: PLA | B10: 10 | C10: =D42 -> 0.0791 | E10: PLA | F10: 12 | G10: =I44 -> 0.0704 | I10: PLA | J10: 14 | K10: =I46 -> 0.0907 | M10: =C10 -> 0.0791 | N10: =G10 -> 0.0704 | O10: =K10 -> 0.0907
A11: PLA | B11: 11 | C11: =D43 -> 0.1307 | E11: PLA | F11: 13 | G11: =I45 -> 0.1337 | I11: PLA | J11: 15 | K11: =I47 -> 0.0663 | M11: =C11 -> 0.1307 | N11: =G11 -> 0.1337 | O11: =K11 -> 0.0663
A12: PETG | B12: 4 | C12: =D44 -> 0.0202 | E12: PETG | F12: 6 | G12: =N38 -> 0.0752 | I12: PETG | J12: 8 | K12: =N40 -> 0.0401 | M12: =C12 -> 0.0202 | N12: =G12 -> 0.0752 | O12: =K12 -> 0.0401
A13: PETG | B13: 5 | C13: =D45 -> 0.1067 | E13: PETG | F13: 7 | G13: =N39 -> 0.1185 | I13: PETG | J13: 9 | K13: =N41 -> 0.1204 | M13: =C13 -> 0.1067 | N13: =G13 -> 0.1185 | O13: =K13 -> 0.1204
A14: PETG | B14: 10 | C14: =D46 -> 0.0392 | E14: PETG | F14: 12 | G14: =N44 -> 0.0723 | I14: PETG | J14: 14 | K14: =N46 -> 0.0455 | M14: =C14 -> 0.0392 | N14: =G14 -> 0.0723 | O14: =K14 -> 0.0455
A15: PETG | B15: 11 | C15: =D47 -> 0.0969 | E15: PETG | F15: 13 | G15: =N45 -> 0.0455 | I15: PETG | J15: 15 | K15: =N47 -> 0.0794 | M15: =C15 -> 0.0969 | N15: =G15 -> 0.0455 | O15: =K15 -> 0.0794
A16: Infill | B16: Average Modulus of Resilience
A17: Grid | B17: =AVERAGE(C4:C15) -> 0.062016667
A18: Cubic | B18: =AVERAGE(G4:G15) -> 0.078125
A19: Gyroid | B19: =AVERAGE(K4:K15) -> 0.071191667
A21: Max Difference: | B21: =(1-B19/B17) -> -0.1479441
A34: ABS | F34: PLA | K34: PETG
A35: Index Value | B35: Infill Type | C35: Mass (g) | D35: Modulus of Resilience (MPa) | F35: Index Value | G35: Infill Type | H35: Mass (g) | I35: Modulus of Resilience (MPa) | K35: Index Value | L35: Infill Type | M35: Mass (g) | N35: Modulus of Resilience (MPa)
A36: 4 | B36: Grid | C36: 19.2 | D36: 0.0207 | F36: 4 | G36: Grid | H36: 23 | I36: 0.0798 | K36: 4 | L36: Grid | M36: 24.4 | N36: 0.0994
A37: 5 | B37: Grid | C37: 26 | D37: 0.061 | F37: 5 | G37: Grid | H37: 35.1 | I37: 0.135 | K37: 5 | L37: Grid | M37: 35.5 | N37: 0.2044
A38: 6 | B38: Cubic | C38: 19 | D38: 0.0161 | F38: 6 | G38: Cubic | H38: 22.9 | I38: 0.0673 | K38: 6 | L38: Cubic | M38: 22.5 | N38: 0.0752
A39: 7 | B39: Cubic | C39: 26.1 | D39: 0.0893 | F39: 7 | G39: Cubic | H39: 31.3 | I39: 0.1223 | K39: 7 | L39: Cubic | M39: 30.8 | N39: 0.1185
A40: 8 | B40: Gyroid | C40: 19 | D40: 0.0587 | F40: 8 | G40: Gyroid | H40: 23 | I40: 0.0814 | K40: 8 | L40: Gyroid | M40: 22.6 | N40: 0.0401
A41: 9 | B41: Gyroid | C41: 25.6 | D41: 0.0256 | F41: 9 | G41: Gyroid | H41: 31 | I41: 0.1101 | K41: 9 | L41: Gyroid | M41: 30.5 | N41: 0.1204
A42: 10 | B42: Grid | C42: 24.5 | D42: 0.0791 | F42: 10 | G42: Grid | H42: 29.6 | I42: 0.1157 | K42: 10 | L42: Grid | M42: 29.2 | N42: 0.0885
A43: 11 | B43: Grid | C43: 30.8 | D43: 0.1307 | F43: 11 | G43: Grid | H43: 36.9 | I43: 0.1236 | K43: 11 | L43: Grid | M43: 36.1 | N43: 0.1659
A44: 12 | B44: Cubic | C44: 24.6 | D44: 0.0202 | F44: 12 | G44: Cubic | H44: 29.5 | I44: 0.0704 | K44: 12 | L44: Cubic | M44: 28.9 | N44: 0.0723
A45: 13 | B45: Cubic | C45: 30.8 | D45: 0.1067 | F45: 13 | G45: Cubic | H45: 36.9 | I45: 0.1337 | K45: 13 | L45: Cubic | M45: 36.2 | N45: 0.0455
A46: 14 | B46: Gyroid | C46: 24.6 | D46: 0.0392 | F46: 14 | G46: Gyroid | H46: 29.8 | I46: 0.0907 | K46: 14 | L46: Gyroid | M46: 29.2 | N46: 0.0455
A47: 15 | B47: Gyroid | C47: 30.4 | D47: 0.0969 | F47: 15 | G47: Gyroid | H47: 36.8 | I47: 0.0663 | K47: 15 | L47: Gyroid | M47: 35.9 | N47: 0.0794

Sheet Infill Style Comparison - YS
A2: Grid | E2: Cubic | I2: Gyroid
A3: Material | B3: Index | C3: Yield Strength (kN) | E3: Material | F3: Index | G3: Yield Strength (kN) | I3: Material | J3: Index | K3: Yield Strength (kN) | M3: Grid | N3: Cubic | O3: Gyroid
A4: ABS | B4: 4 | C4: =D36 -> 0.5052 | E4: ABS | F4: 6 | G4: =D38 -> 0.4627 | I4: ABS | J4: 8 | K4: =D40 -> 0.8357 | M4: =C4 -> 0.5052 | N4: =G4 -> 0.4627 | O4: =K4 -> 0.8357
A5: ABS | B5: 5 | C5: =D37 -> 0.8843 | E5: ABS | F5: 7 | G5: =D39 -> 1.1915 | I5: ABS | J5: 9 | K5: =D41 -> 0.6075 | M5: =C5 -> 0.8843 | N5: =G5 -> 1.1915 | O5: =K5 -> 0.6075
A6: ABS | B6: 10 | C6: =D38 -> 0.4627 | E6: ABS | F6: 12 | G6: =D44 -> 0.6075 | I6: ABS | J6: 14 | K6: =D46 -> 0.8138 | M6: =C6 -> 0.4627 | N6: =G6 -> 0.6075 | O6: =K6 -> 0.8138
A7: ABS | B7: 11 | C7: =D39 -> 1.1915 | E7: ABS | F7: 13 | G7: =D45 -> 1.4839 | I7: ABS | J7: 15 | K7: =D47 -> 1.3223 | M7: =C7 -> 1.1915 | N7: =G7 -> 1.4839 | O7: =K7 -> 1.3223
A8: PLA | B8: 4 | C8: =D40 -> 0.8357 | E8: PLA | F8: 6 | G8: =I38 -> 1.1478 | I8: PLA | J8: 8 | K8: =I40 -> 1.2307 | M8: =C8 -> 0.8357 | N8: =G8 -> 1.1478 | O8: =K8 -> 1.2307
A9: PLA | B9: 5 | C9: =D41 -> 0.6075 | E9: PLA | F9: 7 | G9: =I39 -> 1.731 | I9: PLA | J9: 9 | K9: =I41 -> 1.5126 | M9: =C9 -> 0.6075 | N9: =G9 -> 1.731 | O9: =K9 -> 1.5126
A10: PLA | B10: 10 | C10: =D42 -> 1.1189 | E10: PLA | F10: 12 | G10: =I44 -> 1.35 | I10: PLA | J10: 14 | K10: =I46 -> 1.4959 | M10: =C10 -> 1.1189 | N10: =G10 -> 1.35 | O10: =K10 -> 1.4959
A11: PLA | B11: 11 | C11: =D43 -> 1.518 | E11: PLA | F11: 13 | G11: =I45 -> 2.0056 | I11: PLA | J11: 15 | K11: =I47 -> 1.401 | M11: =C11 -> 1.518 | N11: =G11 -> 2.0056 | O11: =K11 -> 1.401
A12: PETG | B12: 4 | C12: =D44 -> 0.6075 | E12: PETG | F12: 6 | G12: =N38 -> 0.8549 | I12: PETG | J12: 8 | K12: =N40 -> 0.6326 | M12: =C12 -> 0.6075 | N12: =G12 -> 0.8549 | O12: =K12 -> 0.6326
A13: PETG | B13: 5 | C13: =D45 -> 1.4839 | E13: PETG | F13: 7 | G13: =N39 -> 1.2204 | I13: PETG | J13: 9 | K13: =N41 -> 1.1699 | M13: =C13 -> 1.4839 | N13: =G13 -> 1.2204 | O13: =K13 -> 1.1699
A14: PETG | B14: 10 | C14: =D46 -> 0.8138 | E14: PETG | F14: 12 | G14: =N44 -> 1.0249 | I14: PETG | J14: 14 | K14: =N46 -> 0.8203 | M14: =C14 -> 0.8138 | N14: =G14 -> 1.0249 | O14: =K14 -> 0.8203
A15: PETG | B15: 11 | C15: =D47 -> 1.3223 | E15: PETG | F15: 13 | G15: =N45 -> 0.9262 | I15: PETG | J15: 15 | K15: =N47 -> 1.1319 | M15: =C15 -> 1.3223 | N15: =G15 -> 0.9262 | O15: =K15 -> 1.1319
A16: Infill | B16: Average Yield Strength
A17: Grid | B17: =AVERAGE(C4:C15) -> 0.94594167
A18: Cubic | B18: =AVERAGE(G4:G15) -> 1.1672
A19: Gyroid | B19: =AVERAGE(K4:K15) -> 1.0811833
A34: ABS | F34: PLA | K34: PETG
A35: Index Value | B35: Infill Type | C35: Mass (g) | D35: Yield Strength (kN) | F35: Index Value | G35: Infill Type | H35: Mass (g) | I35: Yield Strength (kN) | K35: Index Value | L35: Infill Type | M35: Mass (g) | N35: Yield Strength (kN)
A36: 4 | B36: Grid | C36: 19.2 | D36: 0.5052 | F36: 4 | G36: Grid | H36: 23 | I36: 1.1251 | K36: 4 | L36: Grid | M36: 24.4 | N36: 1.0671
A37: 5 | B37: Grid | C37: 26 | D37: 0.8843 | F37: 5 | G37: Grid | H37: 35.1 | I37: 1.7471 | K37: 5 | L37: Grid | M37: 35.5 | N37: 1.5927
A38: 6 | B38: Cubic | C38: 19 | D38: 0.4627 | F38: 6 | G38: Cubic | H38: 22.9 | I38: 1.1478 | K38: 6 | L38: Cubic | M38: 22.5 | N38: 0.8549
A39: 7 | B39: Cubic | C39: 26.1 | D39: 1.1915 | F39: 7 | G39: Cubic | H39: 31.3 | I39: 1.731 | K39: 7 | L39: Cubic | M39: 30.8 | N39: 1.2204
A40: 8 | B40: Gyroid | C40: 19 | D40: 0.8357 | F40: 8 | G40: Gyroid | H40: 23 | I40: 1.2307 | K40: 8 | L40: Gyroid | M40: 22.6 | N40: 0.6326
A41: 9 | B41: Gyroid | C41: 25.6 | D41: 0.6075 | F41: 9 | G41: Gyroid | H41: 31 | I41: 1.5126 | K41: 9 | L41: Gyroid | M41: 30.5 | N41: 1.1699
A42: 10 | B42: Grid | C42: 24.5 | D42: 1.1189 | F42: 10 | G42: Grid | H42: 29.6 | I42: 1.7044 | K42: 10 | L42: Grid | M42: 29.2 | N42: 1.1034
A43: 11 | B43: Grid | C43: 30.8 | D43: 1.518 | F43: 11 | G43: Grid | H43: 36.9 | I43: 1.7942 | K43: 11 | L43: Grid | M43: 36.1 | N43: 1.4642
A44: 12 | B44: Cubic | C44: 24.6 | D44: 0.6075 | F44: 12 | G44: Cubic | H44: 29.5 | I44: 1.35 | K44: 12 | L44: Cubic | M44: 28.9 | N44: 1.0249
A45: 13 | B45: Cubic | C45: 30.8 | D45: 1.4839 | F45: 13 | G45: Cubic | H45: 36.9 | I45: 2.0056 | K45: 13 | L45: Cubic | M45: 36.2 | N45: 0.9262
A46: 14 | B46: Gyroid | C46: 24.6 | D46: 0.8138 | F46: 14 | G46: Gyroid | H46: 29.8 | I46: 1.4959 | K46: 14 | L46: Gyroid | M46: 29.2 | N46: 0.8203
A47: 15 | B47: Gyroid | C47: 30.4 | D47: 1.3223 | F47: 15 | G47: Gyroid | H47: 36.8 | I47: 1.401 | K47: 15 | L47: Gyroid | M47: 35.9 | N47: 1.1319

Sheet Infill Density Comparison - UTS
A2: 0 | E2: 0.1 | I2: 0.25
A3: Material | B3: Index | C3: Ultimate Tensile Strength (kN) | E3: Material | F3: Index | G3: Ultimate Tensile Strength (kN) | I3: Material | J3: Index | K3: Ultimate Tensile Strength (kN)
A4: ABS | B4: 2 | C4: =D43 -> 1.6811 | E4: ABS | F4: 4 | G4: =D45 -> 1.335 | I4: ABS | J4: 5 | K4: =D46 -> 1.445
A5: ABS | B5: 3 | C5: =D44 -> 2.8112 | E5: ABS | F5: 6 | G5: =D47 -> 1.4693 | I5: ABS | J5: 7 | K5: =D48 -> 1.8183
A6: PLA | B6: 2 | C6: =I43 -> 1.6182 | E6: ABS | F6: 8 | G6: =D49 -> 1.4343 | I6: ABS | J6: 9 | K6: =D50 -> 1.5629
A7: PLA | B7: 3 | C7: =I44 -> 2.4347 | E7: ABS | F7: 10 | G7: =D51 -> 1.8508 | I7: ABS | J7: 11 | K7: =D52 -> 2.1374
A8: PETG | B8: 2 | C8: =N43 -> 1.5726 | E8: ABS | F8: 12 | G8: =D53 -> 2.0702 | I8: ABS | J8: 13 | K8: =D54 -> 2.3705
A9: PETG | B9: 3 | C9: =N44 -> 2.6493 | E9: ABS | F9: 14 | G9: =D55 -> 1.8688 | I9: ABS | J9: 15 | K9: =D56 -> 2.1361
E10: PLA | F10: 4 | G10: =I45 -> 1.7476 | I10: PLA | J10: 5 | K10: =I46 -> 2.4642
E11: PLA | F11: 6 | G11: =I47 -> 2.1302 | I11: PLA | J11: 7 | K11: =I48 -> 2.6031
E12: PLA | F12: 8 | G12: =I49 -> 2.0438 | I12: PLA | J12: 9 | K12: =I50 -> 2.3404
E13: PLA | F13: 10 | G13: =I51 -> 2.8334 | I13: PLA | J13: 11 | K13: =I52 -> 2.8868
E14: PLA | F14: 12 | G14: =I53 -> 2.8893 | I14: PLA | J14: 13 | K14: =I54 -> 3.2658
E15: PLA | F15: 14 | G15: =I55 -> 2.6368 | I15: PLA | J15: 15 | K15: =I56 -> 3.1633
E16: PETG | F16: 4 | G16: =N45 -> 2.0192 | I16: PETG | J16: 5 | K16: =N46 -> 2.3
E17: PETG | F17: 6 | G17: =N47 -> 1.7901 | I17: PETG | J17: 7 | K17: =N48 -> 2.2188
E18: PETG | F18: 8 | G18: =N49 -> 1.7519 | I18: PETG | J18: 9 | K18: =N50 -> 2.1164
E19: PETG | F19: 10 | G19: =N51 -> 2.3268 | I19: PETG | J19: 11 | K19: =N52 -> 2.5102
E20: PETG | F20: 12 | G20: =N53 -> 2.5668 | I20: PETG | J20: 13 | K20: =N54 -> 2.9684
E21: PETG | F21: 14 | G21: =N55 -> 2.4034 | I21: PETG | J21: 15 | K21: =N56 -> 2.6422
A22: Infill | B22: Average Ultimate Strength
A23: 0 | B23: =AVERAGE(C4:C21) -> 2.12785
A24: 0.1 | B24: =AVERAGE(G4:G21) -> 2.0648722
A25: 0.25 | B25: =AVERAGE(K4:K21) -> 2.3861
A27: Max Difference: | B27: =(1-B23/B24) -> -0.0304996
A40: ABS | F40: PLA | K40: PETG
A41: Index Value | B41: Infill Concentration | C41: Mass (g) | D41: Ultimate Tensile Strength (kN) | F41: Index Value | G41: Infill Concentration | H41: Mass (g) | I41: Ultimate Tensile Strength (kN) | K41: Index Value | L41: Infill Concentration | M41: Mass (g) | N41: Ultimate Tensile Strength (kN) | P41: 0 | Q41: 0.1 | R41: 0.25
A42: 1 | B42: 1 | C42: 61.3 | D42: 6.6299 | F42: 1 | G42: 1 | H42: 73 | I42: 9.3463 | K42: 1 | L42: 1 | M42: 74.6 | N42: 9.6693 | P42: 1.6811 | Q42: 1.335 | R42: 1.445
A43: 2 | B43: 0 | C43: 20 | D43: 1.6811 | F43: 2 | G43: 0 | H43: 16.7 | I43: 1.6182 | K43: 2 | L43: 0 | M43: 18 | N43: 1.5726 | P43: 2.8112 | Q43: 1.4693 | R43: 1.8183
A44: 3 | B44: 0 | C44: 25.5 | D44: 2.8112 | F44: 3 | G44: 0 | H44: 24.1 | I44: 2.4347 | K44: 3 | L44: 0 | M44: 26.7 | N44: 2.6493 | P44: 1.6182 | Q44: 1.4343 | R44: 1.5629
A45: 4 | B45: 0.1 | C45: 19.2 | D45: 1.335 | F45: 4 | G45: 0.1 | H45: 23 | I45: 1.7476 | K45: 4 | L45: 0.1 | M45: 24.4 | N45: 2.0192 | P45: 2.4347 | Q45: 1.8508 | R45: 2.1374
A46: 5 | B46: 0.25 | C46: 26 | D46: 1.445 | F46: 5 | G46: 0.25 | H46: 35.1 | I46: 2.4642 | K46: 5 | L46: 0.25 | M46: 35.5 | N46: 2.3 | P46: 1.5726 | Q46: 2.0702 | R46: 2.3705
A47: 6 | B47: 0.1 | C47: 19 | D47: 1.4693 | F47: 6 | G47: 0.1 | H47: 22.9 | I47: 2.1302 | K47: 6 | L47: 0.1 | M47: 22.5 | N47: 1.7901 | P47: 2.6493 | Q47: 1.8688 | R47: 2.1361
A48: 7 | B48: 0.25 | C48: 26.1 | D48: 1.8183 | F48: 7 | G48: 0.25 | H48: 31.3 | I48: 2.6031 | K48: 7 | L48: 0.25 | M48: 30.8 | N48: 2.2188 | Q48: 1.7476 | R48: 2.4642
A49: 8 | B49: 0.1 | C49: 19 | D49: 1.4343 | F49: 8 | G49: 0.1 | H49: 23 | I49: 2.0438 | K49: 8 | L49: 0.1 | M49: 22.6 | N49: 1.7519 | Q49: 2.1302 | R49: 2.6031
